Workbook

Sheet n=25
A1: instance_id | B1: repo_full_name | C1: language | D1: difficulty_label | E1: issue_type_primary | F1: repo_type_primary | G1: code_type_primary | H1: long_horizon_tag | I1: stars | J1: loc_value | K1: pr_merged_at | L1: harbor_deliverable_url | M1: deliverable_url | N1: pr_url | T1: Basic Data Summary
A2: deepset-ai__haystack-9680 | B2: deepset-ai/haystack | C2: Python | D2: Medium | E2: feature-request | F2: ai-ml | G2: feature | H2: multi-component-feature | I2: 23283 | J2: 496546 | K2: 45875.608 | L2: https://drive.google.com/drive/folders/1_GD8fDtHHpt3M6VCLxP8ad_p_3W6tkpy | M2: https://drive.google.com/drive/folders/1oa7-DAboVKDtmJFns7feqhKh-929Ir0Z | N2: https://github.com/deepset-ai/haystack/issues/9680
A3: akkadotnet__akka.net-7444 | B3: akkadotnet/akka.net | C3: C# | D3: Medium | E3: feature-request | F3: webdev | G3: feature | H3: multi-component-feature | I3: 4976 | J3: 413595 | K3: 45665.937 | L3: https://drive.google.com/drive/folders/1TEK4hUKn_AW94ntovYadxDXZdxwlrAqm | M3: https://drive.google.com/drive/folders/1KBzqNnl02pikqkDvHEZDjik6gqElCSV6 | N3: https://github.com/akkadotnet/akka.net/issues/7444 | T3: Metric | U3: Value | X3: Language mix
A4: TedDriggs__darling-363 | B4: TedDriggs/darling | C4: Rust | D4: Medium | E4: feature-request | F4: devtools | G4: feature | H4: multi-component-feature | I4: 1186 | J4: 12701 | K4: 45870.799 | L4: https://drive.google.com/drive/folders/1QNiqDzUI3qr8IW6uek6BUeGcOli8ivsV | M4: gs://swe-bench-plus/evaluations/019b0df7-ade4-70bc-89dc-2dc1c6248f76-TedDriggs__darling-363-swe-agent-claude-opus-4.5 | N4: https://github.com/TedDriggs/darling/issues/363 | T4: Total selections | U4: =COUNTA(#REF!) -> 1 | X4: Category | Y4: Count | Z4: Share
A5: 0xMiden__miden-vm-1971 | B5: 0xMiden/miden-vm | C5: Rust | D5: Medium | E5: feature-request | F5: blockchain | G5: feature | H5: multi-component-feature | I5: 697 | J5: 102459 | K5: 45849.803 | L5: https://drive.google.com/drive/folders/10ESmICg53p5aCezkQcQBoyCzIdFiMHzJ | M5: https://drive.google.com/drive/folders/1Q5032tvEX-g-ilz6_53LA10y1u2O-oGC | N5: https://github.com/0xMiden/miden-vm/issues/1971 | T5: Languages | U5: 8 | X5: Go | Y5: =COUNTIF($C$2:$C$38,X5) -> 7 | Z5: =Y5/COUNTA($C$2:$C$38) -> 0.28
A6: kubernetes-sigs__aws-ebs-csi-driver-2467 | B6: kubernetes-sigs/aws-ebs-csi-driver | C6: Go | D6: Hard | E6: chore | F6: infra-devops | G6: refactor | H6: multi-component-feature | I6: 1105 | J6: 51202 | K6: 45786.584 | L6: https://drive.google.com/drive/folders/1gijpPd-rMdTURMnsfHsQiWTQiY49ekvK | M6: gs://swe-bench-plus/evaluations/019b6aa7-0380-771f-9e02-24cda0fe6639-kubernetes-sigs__aws-ebs-csi-driver-2467-swe-agent-claude-sonnet-4.5 | N6: https://github.com/kubernetes-sigs/aws-ebs-csi-driver/issues/2467 | T6: Issue types | U6: 3 | X6: Python | Y6: =COUNTIF($C$2:$C$38,X6) -> 4 | Z6: =Y6/COUNTA($C$2:$C$38) -> 0.16
A7: cedarcode__webauthn-ruby-459 | B7: cedarcode/webauthn-ruby | C7: Ruby | D7: Hard | E7: chore | F7: security | G7: refactor | H7: transitive-dependency-repair | I7: 732 | J7: 8630 | K7: 45800.769 | L7: https://drive.google.com/drive/folders/1SXYFmv65VSQRCqoTaJOieIL4rcYCfkPz | M7: gs://swe-bench-plus/evaluations/019b6aaf-1788-707e-b6dd-d4dc12d72279-cedarcode__webauthn-ruby-459-swe-agent-claude-sonnet-4.5 | N7: https://github.com/cedarcode/webauthn-ruby/issues/459 | T7: Repo types | U7: 9 | X7: TypeScript | Y7: =COUNTIF($C$2:$C$38,X7) -> 4 | Z7: =Y7/COUNTA($C$2:$C$38) -> 0.16
A8: inocan-group__vue3-google-map-351 | B8: inocan-group/vue3-google-map | C8: TypeScript | D8: Hard | E8: chore | F8: webdev | G8: dependency-update | H8: transitive-dependency-repair | I8: 362 | J8: 8363 | K8: 45939.055 | L8: https://drive.google.com/drive/folders/1VsICMzShw2KNjpQRMLoQJ6i3Z_0wTTxK | M8: gs://swe-bench-plus/evaluations/019b6aa7-0380-771f-9e02-24cda0fe6639-inocan-group__vue3-google-map-351-swe-agent-claude-sonnet-4.5 | N8: https://github.com/inocan-group/vue3-google-map/issues/351 | X8: C# | Y8: =COUNTIF($C$2:$C$38,X8) -> 3 | Z8: =Y8/COUNTA($C$2:$C$38) -> 0.12
A9: ovechkin-dm__mockio-89 | B9: ovechkin-dm/mockio | C9: Go | D9: Hard | E9: feature-request | F9: devtools | G9: refactor | H9: transitive-dependency-repair | I9: 189 | J9: 4776 | K9: 45759.491 | L9: https://drive.google.com/drive/folders/15Vtr-JJG_I9JwqUBtJJRNn41_7Edh_oK | M9: gs://swe-bench-plus/evaluations/019b6aa7-0380-771f-9e02-24cda0fe6639-ovechkin-dm__mockio-89-swe-agent-claude-sonnet-4.5 | N9: https://github.com/ovechkin-dm/mockio/issues/89 | X9: Rust | Y9: =COUNTIF($C$2:$C$38,X9) -> 3 | Z9: =Y9/COUNTA($C$2:$C$38) -> 0.12
A10: Azure__template-analyzer-399 | B10: Azure/template-analyzer | C10: C# | D10: Hard | E10: bug-report | F10: security | G10: bug-fix | H10: transitive-dependency-repair | I10: 137 | J10: 25741 | K10: 45882.747 | L10: https://drive.google.com/drive/folders/1qFOtKvH5onggl44jE-UAT92SlUAQQn_d | M10: gs://swe-bench-plus/evaluations/019a25fc-6046-74dd-9a6b-6259f32e9dff-Azure__template-analyzer-399-swe-agent-claude-sonnet-4-20250514 | N10: https://github.com/Azure/template-analyzer/issues/399 | T10: Issue types | X10: Java | Y10: =COUNTIF($C$2:$C$38,X10) -> 2 | Z10: =Y10/COUNTA($C$2:$C$38) -> 0.08
A11: grafana__alloy-3618 | B11: grafana/alloy | C11: Go | D11: Hard | E11: chore | F11: infra-devops | G11: dependency-update | H11: transitive-dependency-repair | I11: 2597 | J11: 365703 | K11: 45796.402 | L11: https://drive.google.com/drive/folders/19tMOF-5HnFRqwNnWNfiWdEIyO6FqH-jY | M11: https://drive.google.com/drive/folders/1OkpzwQNpO9weu9Eo8Ri3zc9NAUQL1fYV | N11: https://github.com/grafana/alloy/issues/3618 | T11: Category | U11: Count | V11: Share | X11: Ruby | Y11: =COUNTIF($C$2:$C$38,X11) -> 1 | Z11: =Y11/COUNTA($C$2:$C$38) -> 0.04
A12: gopherguides__hype-42 | B12: gopherguides/hype | C12: Go | D12: Hard | E12: feature-request | F12: devtools | G12: feature | H12: full-tool-implementation | I12: 52 | J12: 18325 | K12: 45783.053 | L12: https://drive.google.com/drive/folders/1IwgoTHJ3q4myhutDVaYQBy5PkQk7Yn4p | M12: gs://swe-bench-plus/evaluations/019b6ab1-4e74-7019-9e81-9c96e98a145d-gopherguides__hype-42-swe-agent-claude-sonnet-4.5 | N12: https://github.com/gopherguides/hype/issues/42 | T12: feature-request | U12: =COUNTIF($E$2:$E$38,T12) -> 14 | V12: =U12/COUNTA($E$2:$E$38) -> 0.56 | X12: C++ | Y12: =COUNTIF($C$2:$C$38,X12) -> 1 | Z12: =Y12/COUNTA($C$2:$C$38) -> 0.04
A13: actor-framework__actor-framework-1643 | B13: actor-framework/actor-framework | C13: C++ | D13: Hard | E13: feature-request | F13: devtools | G13: feature | H13: full-tool-implementation | I13: 3357 | J13: 139910 | K13: 45235.755 | L13: https://drive.google.com/drive/folders/18x61Pct8CbNMhuUvX0pVdmjUviGmi_Kf | M13: https://drive.google.com/drive/folders/1mvQuqrQFvr0jVMtTdF-UQHW3vUphtxlZ | N13: https://github.com/actor-framework/actor-framework/issues/1643 | T13: bug-report | U13: =COUNTIF($E$2:$E$38,T13) -> 6 | V13: =U13/COUNTA($E$2:$E$38) -> 0.24
A14: blackstork-io__fabric-264 | B14: blackstork-io/fabric | C14: Go | D14: Hard | E14: feature-request | F14: security | G14: feature | H14: full-tool-implementation | I14: 64 | J14: 73635 | K14: 45629.759 | L14: https://drive.google.com/drive/folders/1VdiN55dk8w5kiOfjthsHn0WCFZpq_NlH | M14: gs://swe-bench-plus/evaluations/019b6ab1-4e74-7019-9e81-9c96e98a145d-blackstork-io__fabric-264-swe-agent-claude-sonnet-4.5 | N14: https://github.com/blackstork-io/fabric/issues/264 | T14: chore | U14: =COUNTIF($E$2:$E$38,T14) -> 5 | V14: =U14/COUNTA($E$2:$E$38) -> 0.2
A15: arabold__docs-mcp-server-27 | B15: arabold/docs-mcp-server | C15: TypeScript | D15: Hard | E15: feature-request | F15: ai-ml | G15: feature | H15: full-tool-implementation | I15: 740 | J15: 56112 | K15: 45758.593 | L15: https://drive.google.com/drive/folders/1aoAGTqR2IDAnF7gO0Rje8lL7BPz-NSuA | M15: gs://swe-bench-plus/evaluations/019b6aaf-1788-707e-b6dd-d4dc12d72279-arabold__docs-mcp-server-27-swe-agent-claude-sonnet-4.5 | N15: https://github.com/arabold/docs-mcp-server/issues/27 | X15: Difficulty split
A16: eclipse__openvsx-1327 | B16: eclipse/openvsx | C16: Java | D16: Medium | E16: feature-request | F16: applications | G16: feature | H16: full-tool-implementation | I16: 1651 | J16: 70269 | K16: 45972.232 | L16: https://drive.google.com/drive/folders/1MG6OaJapipUIz0NzjA7DV2MtE2S7dbi6 | M16: gs://swe-bench-plus/evaluations/019bc794-8b97-710a-8eb1-715be5148c6c-eclipse__openvsx-1327-swe-agent-claude-sonnet-4-20250514 | N16: https://github.com/eclipse/openvsx/issues/1327 | T16: Repo types | X16: Category | Y16: Count | Z16: Share
A17: argoproj-labs__hera-1481 | B17: argoproj-labs/hera | C17: Python | D17: Medium | E17: bug-report | F17: data-eng | G17: refactor | H17: code-refactoring-migration | I17: 815 | J17: 118744 | K17: 45884.651 | L17: https://drive.google.com/drive/folders/1GhJIbPLyMg9HY_MQTCffpZkMYY81jzvr | M17: https://drive.google.com/drive/folders/1iZRIJ5-4jqqCJ2aUBVKNArwwSE_Ep6mi | N17: https://github.com/argoproj-labs/hera/issues/1481 | T17: Category | U17: Count | V17: Share | X17: Hard | Y17: =COUNTIF($D$2:$D$38,X17) -> 15 | Z17: =Y17/COUNTA($D$2:$D$38) -> 0.6
A18: deepset-ai__haystack-8725 | B18: deepset-ai/haystack | C18: Python | D18: Medium | E18: chore | F18: ai-ml | G18: maintenance | H18: code-refactoring-migration | I18: 23283 | J18: 496546 | K18: 45672.747 | L18: https://drive.google.com/drive/folders/1JY9x8vir8T6VG_Up8wfEO3aactskF_rB | M18: https://drive.google.com/drive/folders/1zBYYlFJJ0hJLGPrVmMu38He_MIGYYfVP | N18: https://github.com/deepset-ai/haystack/issues/8725 | T18: devtools | U18: =COUNTIF($F$2:$F$38,T18) -> 6 | V18: =U18/COUNTA($F$2:$F$38) -> 0.24 | X18: Medium | Y18: =COUNTIF($D$2:$D$38,X18) -> 10 | Z18: =Y18/COUNTA($D$2:$D$38) -> 0.4
A19: openyurtio__openyurt-2316 | B19: openyurtio/openyurt | C19: Go | D19: Hard | E19: feature-request | F19: infra-devops | G19: refactor | H19: code-refactoring-migration | I19: 1910 | J19: 158574 | K19: 45702.032 | L19: https://drive.google.com/drive/folders/1a1uG9A2EaVb4_37RkLwh2ZqiubfeyON3 | M19: gs://swe-bench-plus/evaluations/019b6aaf-1788-707e-b6dd-d4dc12d72279-openyurtio__openyurt-2316-swe-agent-claude-sonnet-4.5 | N19: https://github.com/openyurtio/openyurt/issues/2316 | T19: infra-devops | U19: =COUNTIF($F$2:$F$38,T19) -> 4 | V19: =U19/COUNTA($F$2:$F$38) -> 0.16
A20: formwerkjs__formwerk-76 | B20: formwerkjs/formwerk | C20: TypeScript | D20: Hard | E20: feature-request | F20: webdev | G20: feature | H20: code-refactoring-migration | I20: 396 | J20: 30342 | K20: 45619.14 | L20: https://drive.google.com/drive/folders/18ZrWYSlaarH7B2Az2Xw7d2EiTIw3DKQ0 | M20: gs://swe-bench-plus/evaluations/019b6aaf-1788-707e-b6dd-d4dc12d72279-formwerkjs__formwerk-76-swe-agent-claude-sonnet-4.5 | N20: https://github.com/formwerkjs/formwerk/issues/76 | T20: ai-ml | U20: =COUNTIF($F$2:$F$38,T20) -> 3 | V20: =U20/COUNTA($F$2:$F$38) -> 0.12
A21: ethereum-optimism__superchain-registry-951 | B21: ethereum-optimism/superchain-registry | C21: Go | D21: Hard | E21: feature-request | F21: blockchain | G21: feature | H21: code-refactoring-migration | I21: 204 | J21: 18961 | K21: 45757.641 | L21: https://drive.google.com/drive/folders/1D0xFtPErDPotZix1dKOMlz4racadE4hP | M21: gs://swe-bench-plus/evaluations/019b6aa7-0380-771f-9e02-24cda0fe6639-ethereum-optimism__superchain-registry-951-swe-agent-claude-sonnet-4.5 | N21: https://github.com/ethereum-optimism/superchain-registry/issues/951 | T21: webdev | U21: =COUNTIF($F$2:$F$38,T21) -> 3 | V21: =U21/COUNTA($F$2:$F$38) -> 0.12
A22: Peternator7__strum-391 | B22: Peternator7/strum | C22: Rust | D22: Medium | E22: bug-report | F22: devtools | G22: feature | H22: repo-evolution-replay | I22: 2190 | J22: 5619 | K22: 45641.976 | L22: https://drive.google.com/drive/folders/1v_D5KhiY2MABxxaHPoSSgSh9wuEV8wlt | M22: gs://swe-bench-plus/evaluations/019a850a-f25b-779a-b3d5-48edf0cdebff-Peternator7__strum-391-swe-agent-claude-sonnet-4-20250514 | N22: https://github.com/Peternator7/strum/issues/391 | T22: security | U22: =COUNTIF($F$2:$F$38,T22) -> 3 | V22: =U22/COUNTA($F$2:$F$38) -> 0.12
A23: apache__gravitino-9839 | B23: apache/gravitino | C23: Java | D23: Medium | E23: bug-report | F23: data-eng | G23: bug-fix | H23: repo-evolution-replay | I23: 2313 | J23: 497894 | K23: 46056.101 | L23: https://drive.google.com/drive/folders/1wWmOswrfXGjP7vxYYTWG4CKOkfHZmZ-b | M23: gs://swe-bench-plus/evaluations/019c6646-ea55-7645-a600-58791210a874-apache__gravitino-9839-swe-agent-claude-sonnet-4-20250514 | N23: https://github.com/apache/gravitino/issues/9839 | T23: blockchain | U23: =COUNTIF($F$2:$F$38,T23) -> 2 | V23: =U23/COUNTA($F$2:$F$38) -> 0.08
A24: geopandas__dask-geopandas-322 | B24: geopandas/dask-geopandas | C24: Python | D24: Medium | E24: bug-report | F24: sci-comp | G24: bug-fix | H24: repo-evolution-replay | I24: 580 | J24: 9354 | K24: 45676.881 | L24: https://drive.google.com/drive/folders/1fGHUf8wvnCijio_zQoMnrUylaUviH2Cw | M24: https://drive.google.com/drive/folders/1tN0LJ86ydkfgDZWaCDkOZvQ24FMTjAAI | N24: https://github.com/geopandas/dask-geopandas/issues/322 | T24: data-eng | U24: =COUNTIF($F$2:$F$38,T24) -> 2 | V24: =U24/COUNTA($F$2:$F$38) -> 0.08
A25: codefori__vscode-db2i-391 | B25: codefori/vscode-db2i | C25: TypeScript | D25: Hard | E25: feature-request | F25: devtools | G25: bug-fix | H25: repo-evolution-replay | I25: 68 | J25: 26458 | K25: 45785.818 | L25: https://drive.google.com/drive/folders/1V6ne529jEz11T1s6Vp1jkn2xOh4VSXop | M25: https://drive.google.com/drive/folders/1a9jJpStkAHKj0jVHp6gN7uPt2OUchAxv | N25: https://github.com/codefori/vscode-db2i/issues/391 | T25: applications | U25: =COUNTIF($F$2:$F$38,T25) -> 1 | V25: =U25/COUNTA($F$2:$F$38) -> 0.04
A26: akkadotnet__akka.net-7720 | B26: akkadotnet/akka.net | C26: C# | D26: Hard | E26: bug-report | F26: infra-devops | G26: bug-fix | H26: repo-evolution-replay | I26: 4976 | J26: 413595 | K26: 45845.719 | L26: https://drive.google.com/drive/folders/1hVnwPST9swAu0WaGQUsq2I__ZqgCI7cq | M26: gs://swe-bench-plus/evaluations/019a25fc-6046-74dd-9a6b-6259f32e9dff-akkadotnet__akka.net-7720-swe-agent-claude-sonnet-4-20250514 | N26: https://github.com/akkadotnet/akka.net/issues/7720 | T26: sci-comp | U26: =COUNTIF($F$2:$F$38,T26) -> 1 | V26: =U26/COUNTA($F$2:$F$38) -> 0.04

Sheet Model_Performance_Comparison_ra
A1: LONG RANGE 25 — RAW PASS@3 INPUT
A2: Rules: reward=1 means resolved. Pass@3=1 if any of the 3 runs resolved the task.
A4: pick_order | B4: instance_id | C4: repo_full_name | D4: language | E4: difficulty_label | F4: issue_type_primary | G4: repo_type_primary | H4: long_horizon_tag | I4: Opus 4.6 run_1_id | J4: Opus 4.6 run_1_result | K4: Opus 4.6 run_2_id | L4: Opus 4.6 run_2_result | M4: Opus 4.6 run_3_id | N4: Opus 4.6 run_3_result | O4: Opus 4.6 success_count | P4: Opus 4.6 pass@3 | Q4: GPT-5.4 run_1_id | R4: GPT-5.4 run_1_result | S4: GPT-5.4 run_2_id | T4: GPT-5.4 run_2_result | U4: GPT-5.4 run_3_id | V4: GPT-5.4 run_3_result | W4: GPT-5.4 success_count | X4: GPT-5.4 exception_count | Y4: GPT-5.4 pass@3 | Z4: Gemini 3.1 Pro run_1_id | AA4: Gemini 3.1 Pro run_1_result | AB4: Gemini 3.1 Pro run_2_id | AC4: Gemini 3.1 Pro run_2_result | AD4: Gemini 3.1 Pro run_3_id | AE4: Gemini 3.1 Pro run_3_result | AF4: Gemini 3.1 Pro success_count | AG4: Gemini 3.1 Pro exception_count | AH4: Gemini 3.1 Pro pass@3 | AI4: models_solved_count | AJ4: solved_by_all_3_models | AK4: solved_by_none
A5: 1 | B5: deepset-ai__haystack-9680 | C5: deepset-ai/haystack | D5: Python | E5: Medium | F5: feature-request | G5: ai-ml | H5: multi-component-feature | I5: deepset-ai__haystack-9680__3RYJwhB | J5: resolved | K5: deepset-ai__haystack-9680__6GZsTqE | L5: resolved | M5: deepset-ai__haystack-9680__HCE7aQh | N5: resolved | O5: 3 | P5: 1 | Q5: deepset-ai__haystack-9680__c5ssHL4 | R5: resolved | S5: deepset-ai__haystack-9680__eZniWbm | T5: resolved | U5: deepset-ai__haystack-9680__p2EEbAq | V5: resolved | W5: 3 | X5: 0 | Y5: 1 | Z5: deepset-ai__haystack-9680__AkeCMZg | AA5: resolved | AB5: deepset-ai__haystack-9680__LxsQznn | AC5: resolved | AD5: deepset-ai__haystack-9680__S2VWdDD | AE5: failure | AF5: 2 | AG5: 0 | AH5: 1 | AI5: 3 | AJ5: 1 | AK5: 0
A6: 2 | B6: akkadotnet__akka.net-7444 | C6: akkadotnet/akka.net | D6: C# | E6: Medium | F6: feature-request | G6: webdev | H6: multi-component-feature | I6: akkadotnet__akka.net-7444__9QE7jmQ | J6: resolved | K6: akkadotnet__akka.net-7444__9AUUwH4 | L6: failure | M6: akkadotnet__akka.net-7444__EHFQfPy | N6: failure | O6: 1 | P6: 1 | Q6: akkadotnet__akka.net-7444__fmku5wM | R6: resolved | S6: akkadotnet__akka.net-7444__yzKhsv6 | T6: resolved | U6: akkadotnet__akka.net-7444__2z7sPsz | V6: failure | W6: 2 | X6: 0 | Y6: 1 | Z6: akkadotnet__akka.net-7444__UPRDMLN | AA6: resolved | AB6: akkadotnet__akka.net-7444__fLkrcef | AC6: resolved | AD6: akkadotnet__akka.net-7444__3VdbPL7 | AE6: failure | AF6: 2 | AG6: 0 | AH6: 1 | AI6: 3 | AJ6: 1 | AK6: 0
A7: 3 | B7: TedDriggs__darling-363 | C7: TedDriggs/darling | D7: Rust | E7: Medium | F7: feature-request | G7: devtools | H7: multi-component-feature | I7: TedDriggs__darling-363__6fiBdsX | J7: resolved | K7: TedDriggs__darling-363__HsNHktG | L7: failure | M7: TedDriggs__darling-363__m8GhSSM | N7: failure | O7: 1 | P7: 1 | Q7: TedDriggs__darling-363__DgWxaph | R7: failure | S7: TedDriggs__darling-363__NLJgHTL | T7: failure | U7: TedDriggs__darling-363__UbMXQX5 | V7: failure | W7: 0 | X7: 0 | Y7: 0 | Z7: TedDriggs__darling-363__7Nc4UUt | AA7: failure | AB7: TedDriggs__darling-363__YE2bphc | AC7: failure | AD7: TedDriggs__darling-363__iMGQLHD | AE7: failure | AF7: 0 | AG7: 0 | AH7: 0 | AI7: 1 | AJ7: 0 | AK7: 0
A8: 4 | B8: 0xMiden__miden-vm-1971 | C8: 0xMiden/miden-vm | D8: Rust | E8: Medium | F8: feature-request | G8: blockchain | H8: multi-component-feature | I8: 0xMiden__miden-vm-1971__TL8xfNZ | J8: failure | K8: 0xMiden__miden-vm-1971__WYFHv8f | L8: failure | M8: 0xMiden__miden-vm-1971__tQUdrgH | N8: failure | O8: 0 | P8: 0 | Q8: 0xMiden__miden-vm-1971__BPTNoSb | R8: failure | S8: 0xMiden__miden-vm-1971__JjjRt5E | T8: failure | U8: 0xMiden__miden-vm-1971__rkwu9Af | V8: failure | W8: 0 | X8: 0 | Y8: 0 | Z8: 0xMiden__miden-vm-1971__b4gHxJD | AA8: failure | AB8: 0xMiden__miden-vm-1971__kYvRZVJ | AC8: failure | AD8: 0xMiden__miden-vm-1971__ovjerZx | AE8: failure | AF8: 0 | AG8: 0 | AH8: 0 | AI8: 0 | AJ8: 0 | AK8: 1
A9: 5 | B9: kubernetes-sigs__aws-ebs-csi-driver-2467 | C9: kubernetes-sigs/aws-ebs-csi-driver | D9: Go | E9: Hard | F9: chore | G9: infra-devops | H9: multi-component-feature | I9: kubernetes-sigs__aws-ebs-csi-dri__3RfDkFp | J9: resolved | K9: kubernetes-sigs__aws-ebs-csi-dri__xbyfkqW | L9: resolved | M9: kubernetes-sigs__aws-ebs-csi-dri__yUG64wf | N9: resolved | O9: 3 | P9: 1 | Q9: kubernetes-sigs__aws-ebs-csi-dri__3f5cysJ | R9: failure | S9: kubernetes-sigs__aws-ebs-csi-dri__R45zj6o | T9: failure | U9: kubernetes-sigs__aws-ebs-csi-dri__YUWvaf3 | V9: failure | W9: 0 | X9: 0 | Y9: 0 | Z9: kubernetes-sigs__aws-ebs-csi-dri__HpxSZ6N | AA9: resolved | AB9: kubernetes-sigs__aws-ebs-csi-dri__UG5UxEb | AC9: resolved | AD9: kubernetes-sigs__aws-ebs-csi-dri__rBRq5Dw | AE9: resolved | AF9: 3 | AG9: 0 | AH9: 1 | AI9: 2 | AJ9: 0 | AK9: 0
A10: 6 | B10: cedarcode__webauthn-ruby-459 | C10: cedarcode/webauthn-ruby | D10: Ruby | E10: Hard | F10: chore | G10: security | H10: transitive-dependency-repair | I10: cedarcode__webauthn-ruby-459__X9ri953 | J10: failure | K10: cedarcode__webauthn-ruby-459__fWJmfuM | L10: failure | M10: cedarcode__webauthn-ruby-459__tnabJjm | N10: failure | O10: 0 | P10: 0 | Q10: cedarcode__webauthn-ruby-459__A4tiino | R10: failure | S10: cedarcode__webauthn-ruby-459__HFBa3iR | T10: failure | U10: cedarcode__webauthn-ruby-459__HtgqccF | V10: failure | W10: 0 | X10: 0 | Y10: 0 | Z10: cedarcode__webauthn-ruby-459__8YGZdSD | AA10: failure | AB10: cedarcode__webauthn-ruby-459__YKhm2pr | AC10: failure | AD10: cedarcode__webauthn-ruby-459__okFnrjR | AE10: failure | AF10: 0 | AG10: 0 | AH10: 0 | AI10: 0 | AJ10: 0 | AK10: 1
A11: 7 | B11: inocan-group__vue3-google-map-351 | C11: inocan-group/vue3-google-map | D11: TypeScript | E11: Hard | F11: chore | G11: webdev | H11: transitive-dependency-repair | I11: inocan-group__vue3-google-map-35__HDgEteQ | J11: failure | K11: inocan-group__vue3-google-map-35__Wm8FrT2 | L11: failure | M11: inocan-group__vue3-google-map-35__vP7C8wZ | N11: failure | O11: 0 | P11: 0 | Q11: inocan-group__vue3-google-map-35__RaxYH8k | R11: failure | S11: inocan-group__vue3-google-map-35__StjpbUx | T11: failure | U11: inocan-group__vue3-google-map-35__osBBAoL | V11: failure | W11: 0 | X11: 3 | Y11: 0 | Z11: inocan-group__vue3-google-map-35__fjuR93b | AA11: failure | AB11: inocan-group__vue3-google-map-35__rFx2nrj | AC11: failure | AD11: inocan-group__vue3-google-map-35__yTtEgas | AE11: failure | AF11: 0 | AG11: 3 | AH11: 0 | AI11: 0 | AJ11: 0 | AK11: 1
A12: 8 | B12: ovechkin-dm__mockio-89 | C12: ovechkin-dm/mockio | D12: Go | E12: Hard | F12: feature-request | G12: devtools | H12: transitive-dependency-repair | I12: ovechkin-dm__mockio-89__EugwiU6 | J12: failure | K12: ovechkin-dm__mockio-89__MijonZA | L12: failure | M12: ovechkin-dm__mockio-89__nTKtxuW | N12: failure | O12: 0 | P12: 0 | Q12: ovechkin-dm__mockio-89__2twNv4N | R12: failure | S12: ovechkin-dm__mockio-89__gFmrwUi | T12: failure | U12: ovechkin-dm__mockio-89__yNNyMFd | V12: failure | W12: 0 | X12: 0 | Y12: 0 | Z12: ovechkin-dm__mockio-89__8sNkYoV | AA12: failure | AB12: ovechkin-dm__mockio-89__8zLQvyf | AC12: failure | AD12: ovechkin-dm__mockio-89__tETq67z | AE12: failure | AF12: 0 | AG12: 0 | AH12: 0 | AI12: 0 | AJ12: 0 | AK12: 1
A13: 9 | B13: Azure__template-analyzer-399 | C13: Azure/template-analyzer | D13: C# | E13: Hard | F13: bug-report | G13: security | H13: transitive-dependency-repair | I13: Azure__template-analyzer-399__MkhHBoo | J13: failure | K13: Azure__template-analyzer-399__Qd9KcGa | L13: failure | M13: Azure__template-analyzer-399__dPNLwMe | N13: failure | O13: 0 | P13: 0 | Q13: Azure__template-analyzer-399__WGiFLmm | R13: failure | S13: Azure__template-analyzer-399__gaGuHdb | T13: failure | U13: Azure__template-analyzer-399__kPrm7V8 | V13: failure | W13: 0 | X13: 0 | Y13: 0 | Z13: Azure__template-analyzer-399__3q5hExj | AA13: failure | AB13: Azure__template-analyzer-399__CWLajNH | AC13: failure | AD13: Azure__template-analyzer-399__qCSYgQL | AE13: failure | AF13: 0 | AG13: 0 | AH13: 0 | AI13: 0 | AJ13: 0 | AK13: 1
A14: 10 | B14: grafana__alloy-3618 | C14: grafana/alloy | D14: Go | E14: Hard | F14: chore | G14: infra-devops | H14: transitive-dependency-repair | I14: grafana__alloy-3618__3Prnh3A | J14: failure | K14: grafana__alloy-3618__LYCJoqq | L14: failure | M14: grafana__alloy-3618__cmAUP8S | N14: failure | O14: 0 | P14: 0 | Q14: grafana__alloy-3618__MYMpcg7 | R14: failure | S14: grafana__alloy-3618__WcdpKSm | T14: failure | U14: grafana__alloy-3618__y9Na5k6 | V14: failure | W14: 0 | X14: 0 | Y14: 0 | Z14: grafana__alloy-3618__HtVLWQ3 | AA14: failure | AB14: grafana__alloy-3618__cGcMRr8 | AC14: failure | AD14: grafana__alloy-3618__eWiEmxG | AE14: failure | AF14: 0 | AG14: 0 | AH14: 0 | AI14: 0 | AJ14: 0 | AK14: 1
A15: 11 | B15: gopherguides__hype-42 | C15: gopherguides/hype | D15: Go | E15: Hard | F15: feature-request | G15: devtools | H15: full-tool-implementation | I15: gopherguides__hype-42__4MnqMYp | J15: failure | K15: gopherguides__hype-42__oqSKFzb | L15: failure | M15: gopherguides__hype-42__tBwwEcr | N15: failure | O15: 0 | P15: 0 | Q15: gopherguides__hype-42__Ca4f39h | R15: failure | S15: gopherguides__hype-42__XnviEf4 | T15: failure | U15: gopherguides__hype-42__Y8GC87F | V15: failure | W15: 0 | X15: 0 | Y15: 0 | Z15: gopherguides__hype-42__PHrhfmL | AA15: failure | AB15: gopherguides__hype-42__WxksP7s | AC15: failure | AD15: gopherguides__hype-42__nPrjk9G | AE15: failure | AF15: 0 | AG15: 0 | AH15: 0 | AI15: 0 | AJ15: 0 | AK15: 1
A16: 12 | B16: actor-framework__actor-framework-1643 | C16: actor-framework/actor-framework | D16: C++ | E16: Hard | F16: feature-request | G16: devtools | H16: full-tool-implementation | I16: actor-framework__actor-framework__KaWHNpD | J16: resolved | K16: actor-framework__actor-framework__eUDMvhw | L16: resolved | M16: actor-framework__actor-framework__iW5CYyQ | N16: resolved | O16: 3 | P16: 1 | Q16: actor-framework__actor-framework__WPehBr4 | R16: resolved | S16: actor-framework__actor-framework__zAcSiVC | T16: resolved | U16: actor-framework__actor-framework__JjREUMK | V16: failure | W16: 2 | X16: 0 | Y16: 1 | Z16: actor-framework__actor-framework__dMMuvhX | AA16: resolved | AB16: actor-framework__actor-framework__oh7Knpx | AC16: resolved | AD16: actor-framework__actor-framework__JQ7zZQh | AE16: failure | AF16: 2 | AG16: 0 | AH16: 1 | AI16: 3 | AJ16: 1 | AK16: 0
... A29: 25 | B29: akkadotnet__akka.net-7720 | C29: akkadotnet/akka.net | D29: C# | E29: Hard | F29: bug-report | G29: infra-devops | H29: repo-evolution-replay | I29: akkadotnet__akka.net-7720__CkHh24i | J29: failure | K29: akkadotnet__akka.net-7720__XW9k6v3 | L29: failure | M29: akkadotnet__akka.net-7720__oZoyLeU | N29: failure | O29: 0 | P29: 0 | Q29: akkadotnet__akka.net-7720__22Rj8BW | R29: failure | S29: akkadotnet__akka.net-7720__7pKr5bK | T29: failure | U29: akkadotnet__akka.net-7720__DWvXMCS | V29: failure | W29: 0 | X29: 0 | Y29: 0 | Z29: akkadotnet__akka.net-7720__oFnmavR | AA29: failure | AB29: akkadotnet__akka.net-7720__oeeHXHc | AC29: failure | AD29: akkadotnet__akka.net-7720__zdQZKCs | AE29: failure | AF29: 0 | AG29: 0 | AH29: 0 | AI29: 0 | AJ29: 0 | AK29: 1

Sheet Samples Metadata & Evals (n=25)
A1: LONG RANGE n=25 tasks — PASS@3 VISUALS
A2: Rules: reward=1 means resolved. Pass@3=1 if any of the 3 runs resolved the task.
A3: Model | B3: Pass@3 resolved tasks | C3: Pass@3 failed tasks | D3: Pass@3 rate | E3: Trial successes | F3: Trial failures | G3: Trial success rate
A4: Opus 4.6 | B4: 10 | C4: 15 | D4: 0.4 | E4: 25 | F4: 50 | G4: 0.33333333
A5: GPT-5.4 | B5: 6 | C5: 19 | D5: 0.24 | E5: 16 | F5: 59 | G5: 0.21333333
A6: Gemini 3.1 Pro | B6: 8 | C6: 17 | D6: 0.32 | E6: 20 | F6: 55 | G6: 0.26666667
A8: Reward Rate (# successful runs / total runs) across 25 tasks * 3 runs each = 75 runs | G8: Reward Rate by Long-Range task type
Y25: Pass@3 by difficulty
Y26: Difficulty | Z26: Task count | AA26: Opus 4.6 | AB26: GPT-5.4 | AC26: Gemini 3.1 Pro
A27: Resolution % (Pass@3) -- a task is considered resolved if at least one attempt (out of 3) succeeded | G27: Resolution % (Pass@3) by Long-Range task type | Y27: Medium | Z27: 10 | AA27: 6 | AB27: 5 | AC27: 5
Y28: Hard | Z28: 15 | AA28: 4 | AB28: 1 | AC28: 3
Y31: Pass@3 by long horizon tag
Y32: Long horizon tag | Z32: Task count | AA32: Opus 4.6 | AB32: GPT-5.4 | AC32: Gemini 3.1 Pro
Y33: multi-component-feature | Z33: 5 | AA33: 4 | AB33: 2 | AC33: 3
Y34: transitive-dependency-repair | Z34: 5 | AA34: 0 | AB34: 0 | AC34: 0
Y35: full-tool-implementation | Z35: 5 | AA35: 2 | AB35: 1 | AC35: 1
Y36: code-refactoring-migration | Z36: 5 | AA36: 3 | AB36: 2 | AC36: 3
Y37: repo-evolution-replay | Z37: 5 | AA37: 1 | AB37: 1 | AC37: 1
Y39: How many models solved each task
Y40: Models solved count | Z40: Task count
Y41: 0 | Z41: 15
Y42: 1 | Z42: 2
Y43: 2 | Z43: 2
Y44: 3 | Z44: 6
A46: Language Distribution of Tasks | D46: Repo Type distribution | G46: Long-Range task type distribution
Y48: Long-Range task type | Z48: Opus successful runs | AA48: Opus total runs | AB48: Opus reward rate | AC48: GPT-5.4 successful runs | AD48: GPT-5.4 total runs | AE48: GPT-5.4 reward rate | AF48: Gemini 3 Pro successful runs | AG48: Gemini 3 Pro total runs | AH48: Gemini 3 Pro reward rate
Y49: code-refactoring-migration | Z49: 9 | AA49: 15 | AB49: 0.6 | AC49: 6 | AD49: 15 | AE49: 0.4 | AF49: 8 | AG49: 15 | AH49: 0.53333333
Y50: multi-component-feature | Z50: 8 | AA50: 15 | AB50: 0.53333333 | AC50: 5 | AD50: 15 | AE50: 0.33333333 | AF50: 7 | AG50: 15 | AH50: 0.46666667
Y51: full-tool-implementation | Z51: 6 | AA51: 15 | AB51: 0.4 | AC51: 2 | AD51: 15 | AE51: 0.13333333 | AF51: 2 | AG51: 15 | AH51: 0.13333333
Y52: repo-evolution-replay | Z52: 2 | AA52: 15 | AB52: 0.13333333 | AC52: 3 | AD52: 15 | AE52: 0.2 | AF52: 3 | AG52: 15 | AH52: 0.2
Y53: transitive-dependency-repair | Z53: 0 | AA53: 15 | AB53: 0 | AC53: 0 | AD53: 15 | AE53: 0 | AF53: 0 | AG53: 15 | AH53: 0
A61: Task-by-task Resolution% (pass@3) details
A62: Instance ID | B62: Language | C62: Difficulty | D62: Opus 4.6 | E62: GPT-5.4 | F62: Gemini 3.1 Pro | G62: Models solved
A63: deepset-ai__haystack-9680 | B63: Python | C63: Medium | D63: 1 | E63: 1 | F63: 1 | G63: 3
A64: akkadotnet__akka.net-7444 | B64: C# | C64: Medium | D64: 1 | E64: 1 | F64: 1 | G64: 3 | Y64: Long-Range task type | Z64: Opus resolved tasks | AA64: Opus total tasks | AB64: Opus Pass@3 | AC64: GPT-5.4 resolved tasks | AD64: GPT-5.4 total tasks | AE64: GPT-5.4 Pass@3 | AF64: Gemini 3 Pro resolved tasks | AG64: Gemini 3 Pro total tasks | AH64: Gemini 3 Pro Pass@3
A65: TedDriggs__darling-363 | B65: Rust | C65: Medium | D65: 1 | E65: 0 | F65: 0 | G65: 1 | Y65: code-refactoring-migration | Z65: 3 | AA65: 5 | AB65: =Z65/AA65 -> 0.6 | AC65: 2 | AD65: 5 | AE65: =AC65/AD65 -> 0.4 | AF65: 3 | AG65: 5 | AH65: =AF65/AG65 -> 0.6
A66: 0xMiden__miden-vm-1971 | B66: Rust | C66: Medium | D66: 0 | E66: 0 | F66: 0 | G66: 0 | Y66: multi-component-feature | Z66: 4 | AA66: 5 | AB66: =Z66/AA66 -> 0.8 | AC66: 2 | AD66: 5 | AE66: =AC66/AD66 -> 0.4 | AF66: 3 | AG66: 5 | AH66: =AF66/AG66 -> 0.6
A67: kubernetes-sigs__aws-ebs-csi-driver-2467 | B67: Go | C67: Hard | D67: 1 | E67: 0 | F67: 1 | G67: 2 | Y67: full-tool-implementation | Z67: 2 | AA67: 5 | AB67: =Z67/AA67 -> 0.4 | AC67: 1 | AD67: 5 | AE67: =AC67/AD67 -> 0.2 | AF67: 1 | AG67: 5 | AH67: =AF67/AG67 -> 0.2
A68: cedarcode__webauthn-ruby-459 | B68: Ruby | C68: Hard | D68: 0 | E68: 0 | F68: 0 | G68: 0 | Y68: repo-evolution-replay | Z68: 1 | AA68: 5 | AB68: =Z68/AA68 -> 0.2 | AC68: 1 | AD68: 5 | AE68: =AC68/AD68 -> 0.2 | AF68: 1 | AG68: 5 | AH68: =AF68/AG68 -> 0.2
A69: inocan-group__vue3-google-map-351 | B69: TypeScript | C69: Hard | D69: 0 | E69: 0 | F69: 0 | G69: 0 | Y69: transitive-dependency-repair | Z69: 0 | AA69: 5 | AB69: =Z69/AA69 -> 0 | AC69: 0 | AD69: 5 | AE69: =AC69/AD69 -> 0 | AF69: 0 | AG69: 5 | AH69: =AF69/AG69 -> 0
...

Sheet Full Dataset Metadata (n=2551)
A1: SweBench++ Long Horizon Range (n=2251) Dataset FactSheet
A2: Summary | O2: Visuals
A3: Total tasks | D3: Languages | G3: Median stars | J3: Median repo LOC
A4: =COUNTA('raw_data_n=2551'!$A$2:$A$2552) -> 2551 | D4: 11 | G4: =MEDIAN('raw_data_n=2551'!$S$2:$S$2552) -> 1005 | J4: =MEDIAN('raw_data_n=2551'!$W$2:$W$2552) -> 99491
A6: Median instance LOC
A7: =MEDIAN('raw_data_n=2551'!$V$2:$V$2552) -> 106
A10: Long Horizon Definition
A11: Long-horizon tasks are software changes that involve multi-step, system-level engineering work, rather than isolated or single-purpose updates. These tasks typically span multiple components, require coordinated changes, and reflect broader evolution of the codebase. We categorize long-horizon tasks into the following 5 types: • Code Refactoring & Migration Large-scale structural changes or technology shifts that affect core architecture or frameworks (e.g., Django → Flask, Python 2 → 3, pip → Poetry, Maven → Gradle, Make → Bazel). These often require coordinated updates across many parts of the codebase. • Repo Evolution Replay Tasks that reproduce or simulate real-world repository evolution over time, often based on release notes or version changes. These involve a sequence of related updates rather than a single isolated change. • Transitive Dependency Repair Changes that originate from dependency updates or core abstraction changes and require fixing all affected downstream components (e.g., updating APIs and adapting all dependent modules accordingly). • Full Tool Implementation Building complete, production-level tools or systems from scratch, rather than adding incremental features. This typically includes core logic, interfaces, and supporting components such as tests or configuration. • Multi-Component Features End-to-end feature development that spans multiple layers or components (e.g., backend, frontend, storage, APIs, and tests), requiring coordinated implementation across the system.
A20: Language distribution | E20: Harbor converted | I20: Long-horizon tag distribution
A21: Category | B21: Count | C21: Share | E21: Category | F21: Count | G21: Share | I21: Category | J21: Count | K21: Share
A22: Python | B22: =COUNTIF('raw_data_n=2551'!$M$2:$M$2552,A22) -> 592 | C22: =B22/COUNTA('raw_data_n=2551'!$A$2:$A$2552) -> 0.23206586 | E22: Converted | F22: =COUNTIF('raw_data_n=2551'!$L$2:$L$2552,"<>") -> 2284 | G22: =F22/COUNTA('raw_data_n=2551'!$A$2:$A$2552) -> 0.89533516 | I22: multi-component-feature | J22: =COUNTIF('raw_data_n=2551'!$B$2:$B$2552,I22) -> 1796 | K22: =J22/COUNTA('raw_data_n=2551'!$A$2:$A$2552) -> 0.70403763
A23: Java | B23: =COUNTIF('raw_data_n=2551'!$M$2:$M$2552,A23) -> 420 | C23: =B23/COUNTA('raw_data_n=2551'!$A$2:$A$2552) -> 0.16464132 | E23: Not converted yet | F23: =COUNTBLANK('raw_data_n=2551'!$L$2:$L$2552) -> 267 | G23: =F23/COUNTA('raw_data_n=2551'!$A$2:$A$2552) -> 0.10466484 | I23: transitive-dependency-repair | J23: =COUNTIF('raw_data_n=2551'!$B$2:$B$2552,I23) -> 233 | K23: =J23/COUNTA('raw_data_n=2551'!$A$2:$A$2552) -> 0.091336731
A24: TypeScript | B24: =COUNTIF('raw_data_n=2551'!$M$2:$M$2552,A24) -> 414 | C24: =B24/COUNTA('raw_data_n=2551'!$A$2:$A$2552) -> 0.1622893 | I24: full-tool-implementation | J24: =COUNTIF('raw_data_n=2551'!$B$2:$B$2552,I24) -> 202 | K24: =J24/COUNTA('raw_data_n=2551'!$A$2:$A$2552) -> 0.079184633
A25: Go | B25: =COUNTIF('raw_data_n=2551'!$M$2:$M$2552,A25) -> 403 | C25: =B25/COUNTA('raw_data_n=2551'!$A$2:$A$2552) -> 0.15797726 | I25: code-refactoring-migration | J25: =COUNTIF('raw_data_n=2551'!$B$2:$B$2552,I25) -> 175 | K25: =J25/COUNTA('raw_data_n=2551'!$A$2:$A$2552) -> 0.068600549
A26: C++ | B26: =COUNTIF('raw_data_n=2551'!$M$2:$M$2552,A26) -> 203 | C26: =B26/COUNTA('raw_data_n=2551'!$A$2:$A$2552) -> 0.079576637 | I26: repo-evolution-replay | J26: =COUNTIF('raw_data_n=2551'!$B$2:$B$2552,I26) -> 145 | K26: =J26/COUNTA('raw_data_n=2551'!$A$2:$A$2552) -> 0.056840455
A27: Rust | B27: =COUNTIF('raw_data_n=2551'!$M$2:$M$2552,A27) -> 152 | C27: =B27/COUNTA('raw_data_n=2551'!$A$2:$A$2552) -> 0.059584477
A28: JavaScript | B28: =COUNTIF('raw_data_n=2551'!$M$2:$M$2552,A28) -> 139 | C28: =B28/COUNTA('raw_data_n=2551'!$A$2:$A$2552) -> 0.054488436
A29: C# | B29: =COUNTIF('raw_data_n=2551'!$M$2:$M$2552,A29) -> 112 | C29: =B29/COUNTA('raw_data_n=2551'!$A$2:$A$2552) -> 0.043904351
A30: Ruby | B30: =COUNTIF('raw_data_n=2551'!$M$2:$M$2552,A30) -> 108 | C30: =B30/COUNTA('raw_data_n=2551'!$A$2:$A$2552) -> 0.042336339
A31: PHP | B31: =COUNTIF('raw_data_n=2551'!$M$2:$M$2552,A31) -> 7 | C31: =B31/COUNTA('raw_data_n=2551'!$A$2:$A$2552) -> 0.002744022
A32: Swift | B32: =COUNTIF('raw_data_n=2551'!$M$2:$M$2552,A32) -> 1 | C32: =B32/COUNTA('raw_data_n=2551'!$A$2:$A$2552) -> 0.00039200314
A35: Stars bucket distribution | E35: Instance LOC distribution | I35: Issue type distribution
A36: Category | B36: Count | C36: Share | E36: Category | F36: Count | G36: Share | I36: Category | J36: Count | K36: Share
A37: 0-100 | B37: =COUNTIFS('raw_data_n=2551'!$S$2:$S$2552,">=-1",'raw_data_n=2551'!$S$2:$S$2552,"<=100") -> 344 | C37: =B37/COUNTA('raw_data_n=2551'!$A$2:$A$2552) -> 0.13484908 | E37: 0-50 | F37: =COUNTIFS('raw_data_n=2551'!$V$2:$V$2552,">=-1",'raw_data_n=2551'!$V$2:$V$2552,"<=50") -> 645 | G37: =F37/COUNTA('raw_data_n=2551'!$A$2:$A$2552) -> 0.25284202 | I37: feature-request | J37: =COUNTIF('raw_data_n=2551'!$F$2:$F$2552,I37) -> 2139 | K37: =J37/COUNTA('raw_data_n=2551'!$A$2:$A$2552) -> 0.83849471
A38: 101-1k | B38: =COUNTIFS('raw_data_n=2551'!$S$2:$S$2552,">100",'raw_data_n=2551'!$S$2:$S$2552,"<=1000") -> 929 | C38: =B38/COUNTA('raw_data_n=2551'!$A$2:$A$2552) -> 0.36417091 | E38: 51-100 | F38: =COUNTIFS('raw_data_n=2551'!$V$2:$V$2552,">50",'raw_data_n=2551'!$V$2:$V$2552,"<=100") -> 576 | G38: =F38/COUNTA('raw_data_n=2551'!$A$2:$A$2552) -> 0.22579381 | I38: bug-report | J38: =COUNTIF('raw_data_n=2551'!$F$2:$F$2552,I38) -> 270 | K38: =J38/COUNTA('raw_data_n=2551'!$A$2:$A$2552) -> 0.10584085
A39: 1k-5k | B39: =COUNTIFS('raw_data_n=2551'!$S$2:$S$2552,">1000",'raw_data_n=2551'!$S$2:$S$2552,"<=5000") -> 675 | C39: =B39/COUNTA('raw_data_n=2551'!$A$2:$A$2552) -> 0.26460212 | E39: 101-250 | F39: =COUNTIFS('raw_data_n=2551'!$V$2:$V$2552,">100",'raw_data_n=2551'!$V$2:$V$2552,"<=250") -> 708 | G39: =F39/COUNTA('raw_data_n=2551'!$A$2:$A$2552) -> 0.27753822 | I39: chore | J39: =COUNTIF('raw_data_n=2551'!$F$2:$F$2552,I39) -> 128 | K39: =J39/COUNTA('raw_data_n=2551'!$A$2:$A$2552) -> 0.050176401
A40: 5k-20k | B40: =COUNTIFS('raw_data_n=2551'!$S$2:$S$2552,">5000",'raw_data_n=2551'!$S$2:$S$2552,"<=20000") -> 376 | C40: =B40/COUNTA('raw_data_n=2551'!$A$2:$A$2552) -> 0.14739318 | E40: 251-500 | F40: =COUNTIFS('raw_data_n=2551'!$V$2:$V$2552,">250",'raw_data_n=2551'!$V$2:$V$2552,"<=500") -> 359 | G40: =F40/COUNTA('raw_data_n=2551'!$A$2:$A$2552) -> 0.14072913 | I40: performance-issue | J40: =COUNTIF('raw_data_n=2551'!$F$2:$F$2552,I40) -> 11 | K40: =J40/COUNTA('raw_data_n=2551'!$A$2:$A$2552) -> 0.0043120345
A41: 20k+ | B41: =COUNTIFS('raw_data_n=2551'!$S$2:$S$2552,">20000") -> 227 | C41: =B41/COUNTA('raw_data_n=2551'!$A$2:$A$2552) -> 0.088984712 | E41: 501-1k | F41: =COUNTIFS('raw_data_n=2551'!$V$2:$V$2552,">500",'raw_data_n=2551'!$V$2:$V$2552,"<=1000") -> 176 | G41: =F41/COUNTA('raw_data_n=2551'!$A$2:$A$2552) -> 0.068992552 | I41: documentation | J41: =COUNTIF('raw_data_n=2551'!$F$2:$F$2552,I41) -> 3 | K41: =J41/COUNTA('raw_data_n=2551'!$A$2:$A$2552) -> 0.0011760094
E42: 1k+ | F42: =COUNTIFS('raw_data_n=2551'!$V$2:$V$2552,">1000") -> 71 | G42: =F42/COUNTA('raw_data_n=2551'!$A$2:$A$2552) -> 0.027832223
E43: Unknown | F43: =COUNTBLANK('raw_data_n=2551'!$V$2:$V$2552) -> 16 | G43: =F43/COUNTA('raw_data_n=2551'!$A$2:$A$2552) -> 0.0062720502
A46: Repository LOC distribution | E46: Difficulty distribution | I46: Code type distribution
A47: Category | B47: Count | C47: Share | E47: Category | F47: Count | G47: Share | I47: Category | J47: Count | K47: Share
A48: 0-10k | B48: =COUNTIFS('raw_data_n=2551'!$W$2:$W$2552,">=-1",'raw_data_n=2551'!$W$2:$W$2552,"<=10000") -> 260 | C48: =B48/COUNTA('raw_data_n=2551'!$A$2:$A$2552) -> 0.10192082 | E48: 1 | F48: =COUNTIF('raw_data_n=2551'!$Q$2:$Q$2552,E48) -> 74 | G48: =F48/COUNT('raw_data_n=2551'!$Q$2:$Q$2552) -> 0.029191321 | I48: feature | J48: =COUNTIF('raw_data_n=2551'!$H$2:$H$2552,I48) -> 2130 | K48: =J48/COUNTA('raw_data_n=2551'!$A$2:$A$2552) -> 0.83496668
A49: 10k-50k | B49: =COUNTIFS('raw_data_n=2551'!$W$2:$W$2552,">10000",'raw_data_n=2551'!$W$2:$W$2552,"<=50000") -> 654 | C49: =B49/COUNTA('raw_data_n=2551'!$A$2:$A$2552) -> 0.25637005 | E49: 2 | F49: =COUNTIF('raw_data_n=2551'!$Q$2:$Q$2552,E49) -> 648 | G49: =F49/COUNT('raw_data_n=2551'!$Q$2:$Q$2552) -> 0.2556213 | I49: bug-fix | J49: =COUNTIF('raw_data_n=2551'!$H$2:$H$2552,I49) -> 262 | K49: =J49/COUNTA('raw_data_n=2551'!$A$2:$A$2552) -> 0.10270482
A50: 50k-100k | B50: =COUNTIFS('raw_data_n=2551'!$W$2:$W$2552,">50000",'raw_data_n=2551'!$W$2:$W$2552,"<=100000") -> 363 | C50: =B50/COUNTA('raw_data_n=2551'!$A$2:$A$2552) -> 0.14229714 | E50: 3 | F50: =COUNTIF('raw_data_n=2551'!$Q$2:$Q$2552,E50) -> 1813 | G50: =F50/COUNT('raw_data_n=2551'!$Q$2:$Q$2552) -> 0.71518738 | I50: refactor | J50: =COUNTIF('raw_data_n=2551'!$H$2:$H$2552,I50) -> 94 | K50: =J50/COUNTA('raw_data_n=2551'!$A$2:$A$2552) -> 0.036848295
A51: 100k-500k | B51: =COUNTIFS('raw_data_n=2551'!$W$2:$W$2552,">100000",'raw_data_n=2551'!$W$2:$W$2552,"<=500000") -> 836 | C51: =B51/COUNTA('raw_data_n=2551'!$A$2:$A$2552) -> 0.32771462 | E51: Missing | F51: =COUNTBLANK('raw_data_n=2551'!$Q$2:$Q$2552) -> 16 | G51: =F51/COUNT('raw_data_n=2551'!$Q$2:$Q$2552) -> 0.0063116371 | I51: dependency-update | J51: =COUNTIF('raw_data_n=2551'!$H$2:$H$2552,I51) -> 43 | K51: =J51/COUNTA('raw_data_n=2551'!$A$2:$A$2552) -> 0.016856135
A52: 500k-1M | B52: =COUNTIFS('raw_data_n=2551'!$W$2:$W$2552,">500000",'raw_data_n=2551'!$W$2:$W$2552,"<=1000000") -> 303 | C52: =B52/COUNTA('raw_data_n=2551'!$A$2:$A$2552) -> 0.11877695 | I52: maintenance | J52: =COUNTIF('raw_data_n=2551'!$H$2:$H$2552,I52) -> 11 | K52: =J52/COUNTA('raw_data_n=2551'!$A$2:$A$2552) -> 0.0043120345
A53: 1M+ | B53: =COUNTIFS('raw_data_n=2551'!$W$2:$W$2552,">1000000") -> 116 | C53: =B53/COUNTA('raw_data_n=2551'!$A$2:$A$2552) -> 0.045472364 | I53: performance | J53: =COUNTIF('raw_data_n=2551'!$H$2:$H$2552,I53) -> 7 | K53: =J53/COUNTA('raw_data_n=2551'!$A$2:$A$2552) -> 0.002744022
A54: Unknown | B54: =COUNTBLANK('raw_data_n=2551'!$W$2:$W$2552) -> 19 | C54: =B54/COUNTA('raw_data_n=2551'!$A$2:$A$2552) -> 0.0074480596 | I54: build-ci | J54: =COUNTIF('raw_data_n=2551'!$H$2:$H$2552,I54) -> 3 | K54: =J54/COUNTA('raw_data_n=2551'!$A$2:$A$2552) -> 0.0011760094
I55: test | J55: =COUNTIF('raw_data_n=2551'!$H$2:$H$2552,I55) -> 1 | K55: =J55/COUNTA('raw_data_n=2551'!$A$2:$A$2552) -> 0.00039200314
...

Sheet raw_data_n=2551
A1: instance_id | B1: long_horizon_tag | C1: pr_url | D1: repo_type_primary | E1: repo_type_relevant | F1: issue_type_primary | G1: issue_type_relevant | H1: code_type_primary | I1: code_type_relevant | J1: created_at | K1: deliverable_url | L1: harbor_deliverable_url | M1: language | N1: repo | O1: repo_full_name | P1: repo_id | Q1: difficulty_score | R1: pr_merged_at | S1: stars | T1: p2p_count | U1: f2p_count | V1: instance_loc | W1: loc
A2: 0x2a-42__lelwel-4 | B2: multi-component-feature | C2: https://github.com/0x2a-42/lelwel/issues/4 | D2: devtools | E2: devtools | F2: feature-request | G2: feature-request | H2: feature | I2: feature;refactor | J2: 46021.505 | K2: gs://swe-bench-plus/evaluations/019b6aaf-1788-707e-b6dd-d4dc12d72279-0x2a-42__lelwel-4-swe-agent-claude-sonnet-4.5 | L2: https://drive.google.com/drive/folders/1LlHIhkRm7oR-lD7kuwyi6Glujfya9hEm | M2: Rust | N2: 0x2a-42/lelwel | O2: 0x2a-42/lelwel | P2: 0x2a-42__lelwel | Q2: 3 | R2: 45649.018 | S2: 181 | T2: 19 | U2: 10 | V2: 1859 | W2: 14096
A3: 0xMiden__miden-base-1421 | B3: multi-component-feature | C3: https://github.com/0xMiden/miden-base/issues/1421 | D3: blockchain | E3: blockchain | F3: feature-request | G3: feature-request;chore | H3: feature | I3: feature;refactor | J3: 45996.655 | K3: https://drive.google.com/drive/folders/16ONI16m86ZIcfDUXJfsRg35R8cV32Lce | L3: https://drive.google.com/drive/folders/1QPBS9OraGcxI49Jqr_R7Q89u3EU22LbF | M3: Rust | N3: 0xMiden/miden-base | O3: 0xMiden/miden-base | P3: 0xMiden__miden-base | Q3: 3 | R3: 45825.833 | S3: 95 | T3: 359 | U3: 6 | V3: 101 | W3: 60795
A4: 0xMiden__miden-vm-1996 | B4: multi-component-feature | C4: https://github.com/0xMiden/miden-vm/issues/1996 | D4: blockchain | E4: blockchain;security | F4: feature-request | G4: feature-request | H4: feature | I4: feature;refactor | J4: 45994.721 | K4: https://drive.google.com/drive/folders/1ch_rmum8n1Wo74l_QRXbMIpFuTumHVeg | L4: https://drive.google.com/drive/folders/14Iqe0ntCd4-fpj376ZjBzr5ab7YTkRJY | M4: Rust | N4: 0xMiden/miden-vm | O4: 0xMiden/miden-vm | P4: 0xMiden__miden-vm | Q4: 3 | R4: 45868.236 | S4: 705 | T4: 2167 | U4: 9 | V4: 100 | W4: 102459
A5: 0xMiden__miden-vm-1941 | B5: multi-component-feature | C5: https://github.com/0xMiden/miden-vm/issues/1941 | D5: blockchain | E5: blockchain;security;infra-devops | F5: feature-request | G5: feature-request;documentation | H5: feature | I5: feature;documentation | J5: 45989.865 | K5: gs://swe-bench-plus/evaluations/019ac789-4ba4-708b-ae17-2b559b5f6cf3-0xMiden__miden-vm-1941-open-hands-claude-sonnet-4-20250514 | L5: https://drive.google.com/drive/folders/1H5sS_HlaGO9tzjuF17Yb6xJ7FkXUCxeX | M5: Rust | N5: 0xMiden/miden-vm | O5: 0xMiden/miden-vm | P5: 0xMiden__miden-vm | Q5: 3 | R5: 45846.646 | S5: 705 | T5: 112 | U5: 1 | V5: 19 | W5: 102459
A6: 0xMiden__miden-vm-1997 | B6: multi-component-feature | C6: https://github.com/0xMiden/miden-vm/issues/1997 | D6: blockchain | E6: blockchain;security | F6: feature-request | G6: feature-request | H6: feature | I6: feature;refactor | J6: 45994.722 | K6: gs://swe-bench-plus/evaluations/0199cf73-9ae4-732f-9d08-b5169ce19959-0xMiden__miden-vm-1997-open-hands-claude-sonnet-4-20250514 | L6: https://drive.google.com/drive/folders/1ZwzJmqglvy2iJF-59j8xxSdXygqUHcX9 | M6: Rust | N6: 0xMiden/miden-vm | O6: 0xMiden/miden-vm | P6: 0xMiden__miden-vm | Q6: 3 | R6: 45860.84 | S6: 705 | T6: 1646 | U6: 2 | V6: 303 | W6: 102459
A7: 11ty__webc-229 | B7: transitive-dependency-repair | C7: https://github.com/11ty/webc/issues/229 | D7: webdev | E7: webdev;devtools | F7: chore | G7: chore | H7: dependency-update | I7: dependency-update;refactor | J7: 46021.509 | K7: gs://swe-bench-plus/evaluations/019b6ab1-4e74-7019-9e81-9c96e98a145d-11ty__webc-229-swe-agent-claude-sonnet-4.5 | L7: https://drive.google.com/drive/folders/1TYF3ckNC1yB07cFD3CuhFvN8PS9hyWGD | M7: JavaScript | N7: 11ty/webc | O7: 11ty/webc | P7: 11ty__webc | Q7: 3 | R7: 45874.919 | S7: 1409 | T7: 321 | U7: 35 | V7: 331 | W7: 7744
A8: 5cript__interval-tree-45 | B8: full-tool-implementation | C8: https://github.com/5cript/interval-tree/issues/45 | D8: sci-comp | E8: sci-comp;graphics-media | F8: feature-request | G8: feature-request | H8: feature | I8: feature;documentation;build-ci | J8: 46021.494 | K8: gs://swe-bench-plus/evaluations/019b6aa7-0380-771f-9e02-24cda0fe6639-5cript__interval-tree-45-swe-agent-claude-sonnet-4.5 | L8: https://drive.google.com/drive/folders/1ielaC0XyWyuFqm3prKyK6wVtQiuC5rLt | M8: C++ | N8: 5cript/interval-tree | O8: 5cript/interval-tree | P8: 5cript__interval-tree | Q8: 3 | R8: 45666.469 | S8: 69 | T8: 105 | U8: 18 | V8: 220 | W8: 7546
A9: a-chacon__oas_rails-106 | B9: multi-component-feature | C9: https://github.com/a-chacon/oas_rails/issues/106 | D9: devtools | E9: devtools;webdev | F9: feature-request | G9: feature-request;documentation | H9: feature | I9: feature;documentation | J9: 46021.494 | K9: gs://swe-bench-plus/evaluations/019b6aa7-0380-771f-9e02-24cda0fe6639-a-chacon__oas_rails-106-swe-agent-claude-sonnet-4.5 | L9: https://drive.google.com/drive/folders/1DZAkZ727LmIIYTGpT_X8dFA3ImC0LU7Z | M9: Ruby | N9: a-chacon/oas_rails | O9: a-chacon/oas_rails | P9: a-chacon__oas_rails | Q9: 3 | R9: 45759.865 | S9: 166 | T9: 34 | U9: 5 | V9: 16 | W9: 6379
A10: a-chacon__oas_rails-121 | B10: multi-component-feature | C10: https://github.com/a-chacon/oas_rails/issues/121 | D10: devtools | E10: devtools;webdev | F10: feature-request | G10: feature-request | H10: feature | I10: feature;refactor | J10: 45975.679 | K10: https://drive.google.com/drive/folders/1ofb-sezKnj9eX-93_9Kto6V_x0Mh4y4N | L10: https://drive.google.com/drive/folders/1AmOtUUVT3O6mOkZYNjTWWlxN-tJSbp_s | M10: Ruby | N10: a-chacon/oas_rails | O10: a-chacon/oas_rails | P10: a-chacon__oas_rails | Q10: 3 | R10: 45786.776 | S10: 166 | T10: 44 | U10: 23 | V10: 134 | W10: 6379
A11: a-ghorbani__pocketpal-ai-369 | B11: multi-component-feature | C11: https://github.com/a-ghorbani/pocketpal-ai/issues/369 | D11: applications | E11: applications;ai-ml | F11: feature-request | G11: feature-request | H11: feature | I11: feature;refactor | J11: 46021.505 | K11: gs://swe-bench-plus/evaluations/019b6aaf-1788-707e-b6dd-d4dc12d72279-a-ghorbani__pocketpal-ai-369-swe-agent-claude-sonnet-4.5 | L11: https://drive.google.com/drive/folders/1akkiUgdC05P8gR3BipY1f5JmnkG7o7-X | M11: TypeScript | N11: a-ghorbani/pocketpal-ai | O11: a-ghorbani/pocketpal-ai | P11: a-ghorbani__pocketpal-ai | Q11: 3 | R11: 45848.817 | S11: 5712 | T11: 738 | U11: 21 | V11: 364 | W11: 75651
A12: a-ghorbani__pocketpal-ai-148 | B12: multi-component-feature | C12: https://github.com/a-ghorbani/pocketpal-ai/issues/148 | D12: ai-ml | E12: ai-ml;applications | F12: feature-request | G12: feature-request | H12: feature | I12: feature;performance;refactor | J12: 46021.505 | K12: gs://swe-bench-plus/evaluations/019b6aaf-1788-707e-b6dd-d4dc12d72279-a-ghorbani__pocketpal-ai-148-swe-agent-claude-sonnet-4.5 | L12: https://drive.google.com/drive/folders/1ceL8KRwKn-zYBNKqYDosKUrv4lWtGv6U | M12: TypeScript | N12: a-ghorbani/pocketpal-ai | O12: a-ghorbani/pocketpal-ai | P12: a-ghorbani__pocketpal-ai | Q12: 3 | R12: 45652.828 | S12: 5712 | T12: 7 | U12: 2 | V12: 761 | W12: 75651
A13: a2aproject__a2a-dotnet-163 | B13: transitive-dependency-repair | C13: https://github.com/a2aproject/a2a-dotnet/issues/163 | D13: ai-ml | E13: ai-ml;devtools | F13: bug-report | G13: bug-report;chore | H13: bug-fix | I13: bug-fix;dependency-update | J13: 45975.679 | K13: https://drive.google.com/drive/folders/1m7d452EB2fY8kzy4Yx-ILzpE1kKtGjiP | L13: https://drive.google.com/drive/folders/1xFtpkopD3rIBYaJo9JModq4e2ys_8Vuk | M13: C# | N13: a2aproject/a2a-dotnet | O13: a2aproject/a2a-dotnet | P13: a2aproject__a2a-dotnet | Q13: 3 | R13: 45895.98 | S13: 209 | T13: 199 | U13: 4 | V13: 24 | W13: 15259
... A26: achimnol__aiotools-79 | B26: code-refactoring-migration | C26: https://github.com/achimnol/aiotools/issues/79 | D26: devtools | E26: devtools | F26: bug-report | G26: bug-report;chore | H26: bug-fix | I26: bug-fix;refactor;build-ci | J26: 45975.679 | K26: https://drive.google.com/drive/folders/1L7lOEDi0wfGy5yrrI6wtkWVspIac_FOE | L26: https://drive.google.com/drive/folders/1WjFHu_02PpZ2e-VYbMWRcJMYIih8Wq-Y | M26: Python | N26: achimnol/aiotools | O26: achimnol/aiotools | P26: achimnol__aiotools | Q26: 3 | R26: 45810.522 | S26: 162 | T26: 89 | U26: 37 | V26: 646 | W26: 7825
A27: acoular__acoular-368 | B27: full-tool-implementation | C27: https://github.com/acoular/acoular/issues/368 | D27: sci-comp | E27: sci-comp;graphics-media | F27: feature-request | G27: feature-request | H27: feature | I27: feature;documentation;build-ci | J27: 45977.676 | K27: gs://swe-bench-plus/evaluations/019a6f31-5865-7528-b3d7-dd9431bd3aac-acoular__acoular-368-swe-agent-claude-sonnet-4.5 | M27: Python | N27: acoular/acoular | O27: acoular/acoular | P27: acoular__acoular | Q27: 3 | R27: 45623.679 | S27: 584 | T27: 1194 | U27: 6 | V27: 181 | W27: 22397
A28: actions__download-artifact-401 | B28: multi-component-feature | C28: https://github.com/actions/download-artifact/issues/401 | D28: infra-devops | E28: infra-devops;devtools | F28: feature-request | G28: feature-request | H28: feature | I28: feature;documentation | J28: 46021.505 | K28: gs://swe-bench-plus/evaluations/019b6aaf-1788-707e-b6dd-d4dc12d72279-actions__download-artifact-401-swe-agent-claude-sonnet-4.5 | L28: https://drive.google.com/drive/folders/1e-U9w5QPrBq2Tzw9otmjDfXlaKYHDU5x | M28: TypeScript | N28: actions/download-artifact | O28: actions/download-artifact | P28: actions__download-artifact | Q28: 3 | R28: 45769.637 | S28: 1772 | T28: 7 | U28: 7 | V28: 52 | W28: 103621
A29: actions__setup-java-736 | B29: full-tool-implementation | C29: https://github.com/actions/setup-java/issues/736 | D29: infra-devops | E29: infra-devops;devtools | F29: feature-request | G29: feature-request | H29: feature | I29: feature;test;documentation | J29: 46076.632 | K29: gs://swe-bench-plus/evaluations/019c8ad6-24d8-74d7-bfdb-849e95e51fa5-actions__setup-java-736-swe-agent-claude-sonnet-4-20250514 | L29: https://drive.google.com/drive/folders/1A8Ad3_Ol9T2mRI-_Ejkx9xbgQZR4l4bL | M29: TypeScript | N29: actions/setup-java | O29: actions/setup-java | P29: actions__setup-java | Q29: 3 | R29: 45986.817 | S29: 1848 | T29: 26 | U29: 140 | V29: 34 | W29: 285180
A30: actions__setup-node-1240 | B30: multi-component-feature | C30: https://github.com/actions/setup-node/issues/1240 | D30: infra-devops | E30: infra-devops;devtools | F30: feature-request | G30: feature-request | H30: feature | I30: feature;documentation | J30: 45975.679 | K30: https://drive.google.com/drive/folders/1yPiWUsoKtz6QmS-AEluLVSpDi1MA9MRU | L30: https://drive.google.com/drive/folders/12ucPicJNCouhB7xTsr_zowIXsUnRtsZV | M30: TypeScript | N30: actions/setup-node | O30: actions/setup-node | P30: actions__setup-node | Q30: 3 | R30: 45749.66 | S30: 4650 | T30: 46 | U30: 7 | V30: 83 | W30: 158143
A31: actions__setup-node-1348 | B31: full-tool-implementation | C31: https://github.com/actions/setup-node/issues/1348 | D31: infra-devops | E31: infra-devops;devtools | F31: feature-request | G31: feature-request | H31: feature | I31: feature;test;documentation | J31: 45980.939 | K31: gs://swe-bench-plus/evaluations/019a9c38-de10-75b7-94c4-e7ed346fd3eb-actions__setup-node-1348-swe-agent-claude-sonnet-4-20250514 | L31: https://drive.google.com/drive/folders/1VWrWPq5qQ3CynK3-rvhq6eatEYOeM4PQ | M31: TypeScript | N31: actions/setup-node | O31: actions/setup-node | P31: actions__setup-node | Q31: 3 | R31: 45895.111 | S31: 4650 | T31: 28 | U31: 1 | V31: 32 | W31: 158143
A32: activeagents__activeagent-90 | B32: multi-component-feature | C32: https://github.com/activeagents/activeagent/issues/90 | D32: ai-ml | E32: ai-ml;webdev | F32: feature-request | G32: feature-request;documentation | H32: feature | I32: feature;documentation | J32: 46021.505 | K32: gs://swe-bench-plus/evaluations/019b6aaf-1788-707e-b6dd-d4dc12d72279-activeagents__activeagent-90-swe-agent-claude-sonnet-4.5 | L32: https://drive.google.com/drive/folders/10p4D2ipiO57QBNDiowC0t5kuNFYH9z4F | M32: Ruby | N32: activeagents/activeagent | O32: activeagents/activeagent | P32: activeagents__activeagent | Q32: 3 | R32: 45853.875 | S32: 798 | T32: 62 | U32: 3 | V32: 44 | W32: 140141
A33: ActiveLogin__ActiveLogin.Authentication-483 | B33: multi-component-feature | C33: https://github.com/ActiveLogin/ActiveLogin.Authentication/issues/483 | D33: security | E33: security;devtools | F33: feature-request | G33: feature-request | H33: feature | I33: feature;documentation | J33: 46021.493 | K33: gs://swe-bench-plus/evaluations/019b6aa7-0380-771f-9e02-24cda0fe6639-ActiveLogin__ActiveLogin.Authentication-483-swe-agent-claude-sonnet-4.5 | L33: https://drive.google.com/drive/folders/1IuzS1JI-5cwvGgEncaYxLtSAEVKgZz7Z | M33: C# | N33: ActiveLogin/ActiveLogin.Authentication | O33: ActiveLogin/ActiveLogin.Authentication | P33: ActiveLogin__ActiveLogin.Authentication | Q33: 3 | R33: 45674.43 | S33: 230 | T33: 113 | U33: 2 | V33: 141 | W33: 21554
A34: actor-framework__actor-framework-1821 | B34: full-tool-implementation | C34: https://github.com/actor-framework/actor-framework/issues/1821 | D34: devtools | E34: devtools | F34: feature-request | G34: feature-request | H34: feature | I34: feature;test;build-ci | J34: 45975.679 | K34: https://drive.google.com/drive/folders/194t7HN4Krln7KVJuREAAzpM1ROhOCXc- | L34: https://drive.google.com/drive/folders/1SwrYxjwtB7UnFF0-qAgXT5UZ0o9c6eWD | M34: C++ | N34: actor-framework/actor-framework | O34: actor-framework/actor-framework | P34: actor-framework__actor-framework | Q34: 3 | R34: 45374.432 | S34: 3366 | T34: 215 | U34: 1 | V34: 94 | W34: 139910
A35: actor-framework__actor-framework-1643 | B35: full-tool-implementation | C35: https://github.com/actor-framework/actor-framework/issues/1643 | D35: sci-comp | E35: sci-comp;devtools | F35: feature-request | G35: feature-request | H35: feature | I35: feature;test;refactor | J35: 45975.679 | K35: https://drive.google.com/drive/folders/1mvQuqrQFvr0jVMtTdF-UQHW3vUphtxlZ | L35: https://drive.google.com/drive/folders/18x61Pct8CbNMhuUvX0pVdmjUviGmi_Kf | M35: C++ | N35: actor-framework/actor-framework | O35: actor-framework/actor-framework | P35: actor-framework__actor-framework | Q35: 3 | R35: 45235.755 | S35: 3366 | T35: 142 | U35: 1 | V35: 265 | W35: 139910
A36: actor-framework__actor-framework-2067 | B36: multi-component-feature | C36: https://github.com/actor-framework/actor-framework/issues/2067 | D36: sci-comp | E36: sci-comp | F36: feature-request | G36: feature-request | H36: feature | I36: feature;refactor | J36: 45975.679 | K36: https://drive.google.com/drive/folders/11aa5nuY7yEwRY1Eg31YBl9FhBsUIv2Tu | L36: https://drive.google.com/drive/folders/1yerp-f9d9Jm0Fj3z-hJxH9fK4_LJEh54 | M36: C++ | N36: actor-framework/actor-framework | O36: actor-framework/actor-framework | P36: actor-framework__actor-framework | Q36: 3 | R36: 45783.742 | S36: 3366 | T36: 224 | U36: 1 | V36: 292 | W36: 139910
A37: actualbudget__actual-4257 | B37: multi-component-feature | C37: https://github.com/actualbudget/actual/issues/4257 | D37: applications | E37: applications | F37: feature-request | H37: feature | I37: feature;refactor | J37: 45975.679 | K37: https://drive.google.com/drive/folders/1iO5OfeZYgZ9Xj4JhCU5kYQoUDZHeiodo | L37: https://drive.google.com/drive/folders/1UluJwcnQ_e_gvgT8Dhasjtg9OaYtXqCC | M37: TypeScript | N37: actualbudget/actual | O37: actualbudget/actual | P37: actualbudget__actual | Q37: 3 | R37: 45701.995 | S37: 25029 | T37: 10 | U37: 2 | V37: 26 | W37: 999999
A38: actualbudget__actual-4221 | B38: code-refactoring-migration | C38: https://github.com/actualbudget/actual/issues/4221 | D38: applications | E38: applications;webdev | F38: chore | G38: chore | H38: refactor | I38: refactor;maintenance | J38: 46008.629 | K38: https://drive.google.com/drive/folders/1BfQ27VuWDJMrByqeN46HT90x48K1s_LY | L38: https://drive.google.com/drive/folders/1AgDG1nD95UC49IKxhp2d4pIOhlFC61Uq | M38: TypeScript | N38: actualbudget/actual | O38: actualbudget/actual | P38: actualbudget__actual | Q38: 3 | R38: 45707.998 | S38: 25029 | T38: 25 | U38: 131 | V38: 243 | W38: 999999
A39: adamreisnz__replace-in-file-205 | B39: multi-component-feature | C39: https://github.com/adamreisnz/replace-in-file/issues/205 | D39: devtools | E39: devtools | F39: feature-request | G39: feature-request | H39: feature | I39: feature;documentation;refactor | J39: 46021.505 | K39: gs://swe-bench-plus/evaluations/019b6aaf-1788-707e-b6dd-d4dc12d72279-adamreisnz__replace-in-file-205-swe-agent-claude-sonnet-4.5 | L39: https://drive.google.com/drive/folders/1c3zvnwGpzKGuX_GCzhpHaIu0rwP-hzpV | M39: JavaScript | N39: adamreisnz/replace-in-file | O39: adamreisnz/replace-in-file | P39: adamreisnz__replace-in-file | Q39: 3 | R39: 45643.332 | S39: 610 | T39: 121 | U39: 2 | V39: 33 | W39: 2586
A40: AdnaneKhan__gato-x-188 | B40: multi-component-feature | C40: https://github.com/AdnaneKhan/gato-x/issues/188 | D40: security | E40: security;devtools | F40: feature-request | G40: feature-request;documentation | H40: feature | I40: feature;documentation | J40: 46008.629 | K40: https://drive.google.com/drive/folders/13YpbcrEH5vUQxF1ir-icECL5Ad_G_sZD | L40: https://drive.google.com/drive/folders/1EIgLZD1N7sJO7Q_N8OW9l0F9Yod7IVmm | M40: Python | N40: AdnaneKhan/gato-x | O40: AdnaneKhan/gato-x | P40: AdnaneKhan__gato-x | Q40: 3 | R40: 45872.602 | S40: 458 | T40: 487 | U40: 15 | V40: 397 | W40: 26002
A41: adtzlr__felupe-940 | B41: multi-component-feature | C41: https://github.com/adtzlr/felupe/issues/940 | D41: sci-comp | E41: sci-comp;graphics-media | F41: feature-request | G41: feature-request | H41: feature | I41: feature;refactor | J41: 45993.785 | K41: https://drive.google.com/drive/folders/1QgHfO0jY-Hfi50jHKjKQqeNDKFNvQl_u | L41: https://drive.google.com/drive/folders/1JV4o_J_zk2fyFzRpnUMsICfEyz79chOh | M41: Python | N41: adtzlr/felupe | O41: adtzlr/felupe | P41: adtzlr__felupe | Q41: 3 | R41: 45704.871 | S41: 163 | T41: 43 | U41: 4 | V41: 65 | W41: 27461
A42: AFM-SPM__TopoStats-1108 | B42: multi-component-feature | C42: https://github.com/AFM-SPM/TopoStats/issues/1108 | D42: sci-comp | E42: sci-comp;ai-ml;graphics-media | F42: feature-request | G42: feature-request | H42: feature | I42: feature;refactor;documentation | J42: 45975.679 | K42: https://drive.google.com/drive/folders/15oCL7DKSMyQq00sajg0uZBd8jHdHIVKz | L42: https://drive.google.com/drive/folders/1LQvrnsLMRs0nCkKB51bkQejWjK9DCtpN | M42: Python | N42: AFM-SPM/TopoStats | O42: AFM-SPM/TopoStats | P42: AFM-SPM__TopoStats | Q42: 3 | R42: 45733.549 | S42: 75 | T42: 59 | U42: 1 | V42: 57 | W42: 999999
